<?xml version="1.0" encoding="utf-8"?>
<!-- This URDF was automatically created by SolidWorks to URDF Exporter! Originally created by Stephen Brawner (brawner@gmail.com) 
     Commit Version: 1.6.0-1-g15f4949  Build Version: 1.6.7594.29634
     For more information, please see http://wiki.ros.org/sw_urdf_exporter -->
<robot
  name="robot_urdf_infantry">
  <link
    name="base_link">
    <inertial>
      <origin
        xyz="-0.0169183236639579 -0.000182915242454045 0.0690609306536668"
        rpy="0 0 0" />
      <mass
        value="10.1026393048158" />
      <inertia
        ixx="0.0180952613054106"
        ixy="1.08428457198038E-05"
        ixz="-0.000129043293291808"
        iyy="0.0189260916730513"
        iyz="-4.14000287710874E-06"
        izz="0.0306916725800459" />
    </inertial>
    <visual>
      <origin
        xyz="0 0 0"
        rpy="0 0 0" />
      <geometry>
        <mesh
          filename="package://robot_urdf_infantry/meshes/base_link.STL" />
      </geometry>
      <material
        name="">
        <color
          rgba="0.898039215686275 0.917647058823529 0.929411764705882 1" />
      </material>
    </visual>
    <collision>
      <origin
        xyz="0 0 0"
        rpy="0 0 0" />
      <geometry>
        <mesh
          filename="package://robot_urdf_infantry/meshes/base_link.STL" />
      </geometry>
    </collision>
  </link>
  <link
    name="left_forward_wheel_link">
    <inertial>
      <origin
        xyz="-5.60582053621972E-05 0.0195312422532899 -2.66231869774855E-05"
        rpy="0 0 0" />
      <mass
        value="0.20196610038796" />
      <inertia
        ixx="9.03609954075999E-05"
        ixy="-5.05842383427067E-09"
        ixz="2.91601273838805E-07"
        iyy="0.000159661557919175"
        iyz="7.41953648211965E-09"
        izz="9.03046734261075E-05" />
    </inertial>
    <visual>
      <origin
        xyz="0 0 0"
        rpy="0 0 0" />
      <geometry>
        <mesh
          filename="package://robot_urdf_infantry/meshes/left_forward_wheel_link.STL" />
      </geometry>
      <material
        name="">
        <color
          rgba="0.792156862745098 0.819607843137255 0.933333333333333 1" />
      </material>
    </visual>
    <collision>
      <origin
        xyz="0 0 0"
        rpy="0 0 0" />
      <geometry>
        <mesh
          filename="package://robot_urdf_infantry/meshes/left_forward_wheel_link.STL" />
      </geometry>
    </collision>
  </link>
  <joint
    name="base_to_left_forward_wheel_link"
    type="continuous">
    <origin
      xyz="0.1867 0.1991 0.0048"
      rpy="0 0 0" />
    <parent
      link="base_link" />
    <child
      link="left_forward_wheel_link" />
    <axis
      xyz="0 -0.999999999721235 -2.34360814689745E-05" />
    <limit
      effort="380"
      velocity="9999" />
    <safety_controller
      soft_upper="0"
      soft_lower="0"
      k_position="9999"
      k_velocity="9999" />
  </joint>
  <link
    name="right_forward_wheel_link">
    <inertial>
      <origin
        xyz="4.79525151471094E-05 -0.0195312421057282 -3.93945822344966E-05"
        rpy="0 0 0" />
      <mass
        value="0.201966103588379" />
      <inertia
        ixx="9.022074642581E-05"
        ixy="-6.70279305444002E-09"
        ixz="-2.70679291868689E-07"
        iyy="0.000159661390017855"
        iyz="-5.96387817570014E-09"
        izz="9.0444745105792E-05" />
    </inertial>
    <visual>
      <origin
        xyz="0 0 0"
        rpy="0 0 0" />
      <geometry>
        <mesh
          filename="package://robot_urdf_infantry/meshes/right_forward_wheel_link.STL" />
      </geometry>
      <material
        name="">
        <color
          rgba="0.792156862745098 0.819607843137255 0.933333333333333 1" />
      </material>
    </visual>
    <collision>
      <origin
        xyz="0 0 0"
        rpy="0 0 0" />
      <geometry>
        <mesh
          filename="package://robot_urdf_infantry/meshes/right_forward_wheel_link.STL" />
      </geometry>
    </collision>
  </link>
  <joint
    name="base_to_right_forward_wheel_link"
    type="continuous">
    <origin
      xyz="0.1867 -0.1991 0.0048"
      rpy="0 0 0" />
    <parent
      link="base_link" />
    <child
      link="right_forward_wheel_link" />
    <axis
      xyz="0 0.999999999721235 -2.34360814692104E-05" />
    <limit
      effort="380"
      velocity="9999" />
    <safety_controller
      soft_upper="0"
      soft_lower="0"
      k_position="9999"
      k_velocity="9999" />
  </joint>
  <link
    name="left_backward_wheel_link">
    <inertial>
      <origin
        xyz="-4.7951E-05 0.019106 -3.9404E-05"
        rpy="0 0 0" />
      <mass
        value="0.20197" />
      <inertia
        ixx="9.0221E-05"
        ixy="-6.703E-09"
        ixz="2.7068E-07"
        iyy="0.00015966"
        iyz="5.9639E-09"
        izz="9.0445E-05" />
    </inertial>
    <visual>
      <origin
        xyz="0 0 0"
        rpy="0 0 0" />
      <geometry>
        <mesh
          filename="package://robot_urdf_infantry/meshes/left_backward_wheel_link.STL" />
      </geometry>
      <material
        name="">
        <color
          rgba="0.79216 0.81961 0.93333 1" />
      </material>
    </visual>
    <collision>
      <origin
        xyz="0 0 0"
        rpy="0 0 0" />
      <geometry>
        <mesh
          filename="package://robot_urdf_infantry/meshes/left_backward_wheel_link.STL" />
      </geometry>
    </collision>
  </link>
  <joint
    name="base_to_left_backward_wheel_link"
    type="continuous">
    <origin
      xyz="-0.1867 0.1991 0.0048"
      rpy="0 0 0" />
    <parent
      link="base_link" />
    <child
      link="left_backward_wheel_link" />
    <axis
      xyz="0 -1 -2.3436E-05" />
    <limit
      effort="380"
      velocity="9999" />
    <safety_controller
      soft_upper="0"
      soft_lower="0"
      k_position="9999"
      k_velocity="9999" />
  </joint>
  <link
    name="right_backward_wheel_link">
    <inertial>
      <origin
        xyz="5.6058595093611E-05 -0.0195312420324447 -2.66237671080203E-05"
        rpy="0 0 0" />
      <mass
        value="0.20196609976131" />
      <inertia
        ixx="9.03609966068449E-05"
        ixy="-5.05846293664766E-09"
        ixz="-2.9159803548901E-07"
        iyy="0.000159661557381687"
        iyz="-7.42010115197997E-09"
        izz="9.03046717754091E-05" />
    </inertial>
    <visual>
      <origin
        xyz="0 0 0"
        rpy="0 0 0" />
      <geometry>
        <mesh
          filename="package://robot_urdf_infantry/meshes/right_backward_wheel_link.STL" />
      </geometry>
      <material
        name="">
        <color
          rgba="0.792156862745098 0.819607843137255 0.933333333333333 1" />
      </material>
    </visual>
    <collision>
      <origin
        xyz="0 0 0"
        rpy="0 0 0" />
      <geometry>
        <mesh
          filename="package://robot_urdf_infantry/meshes/right_backward_wheel_link.STL" />
      </geometry>
    </collision>
  </link>
  <joint
    name="base_to_right_backward_wheel_link"
    type="continuous">
    <origin
      xyz="-0.1867 -0.1991 0.0048"
      rpy="0 0 0" />
    <parent
      link="base_link" />
    <child
      link="right_backward_wheel_link" />
    <axis
      xyz="0 1 -2.3436E-05" />
    <limit
      effort="380"
      velocity="9999" />
    <safety_controller
      soft_upper="0"
      soft_lower="0"
      k_position="9999"
      k_velocity="9999" />
  </joint>
  <link
    name="yaw_link">
    <inertial>
      <origin
        xyz="-0.018987908986973 -0.0143382651109724 0.0856734317063609"
        rpy="0 0 0" />
      <mass
        value="0.761860614709707" />
      <inertia
        ixx="0.000941047124947946"
        ixy="1.22503489679261E-08"
        ixz="-2.25308184640081E-07"
        iyy="0.00072445952814472"
        iyz="-8.3743957389752E-05"
        izz="0.000595495016456856" />
    </inertial>
    <visual>
      <origin
        xyz="0 0 0"
        rpy="0 0 0" />
      <geometry>
        <mesh
          filename="package://robot_urdf_infantry/meshes/yaw_link.STL" />
      </geometry>
      <material
        name="">
        <color
          rgba="0.898039215686275 0.917647058823529 0.929411764705882 1" />
      </material>
    </visual>
    <collision>
      <origin
        xyz="0 0 0"
        rpy="0 0 0" />
      <geometry>
        <mesh
          filename="package://robot_urdf_infantry/meshes/yaw_link.STL" />
      </geometry>
    </collision>
  </link>
  <joint
    name="base_to_yaw_link"
    type="continuous">
    <origin
      xyz="0.0192509770102757 0 0.151868140587076"
      rpy="0 0 0" />
    <parent
      link="base_link" />
    <child
      link="yaw_link" />
    <axis
      xyz="0 0 -1" />
    <limit
      effort="30"
      velocity="9999" />
    <safety_controller
      soft_upper="0"
      soft_lower="0"
      k_position="9999"
      k_velocity="9999" />
  </joint>
  <link
    name="pitch_link">
    <inertial>
      <origin
        xyz="0.0444973545133058 0.0521717462209072 0.0175897078396731"
        rpy="0 0 0" />
      <mass
        value="0.704098452838613" />
      <inertia
        ixx="0.000395429164724426"
        ixy="8.63718799161938E-06"
        ixz="-5.26064068677351E-06"
        iyy="0.000729854409347408"
        iyz="-6.44701544376519E-10"
        izz="0.000972651052857032" />
    </inertial>
    <visual>
      <origin
        xyz="0 0 0"
        rpy="0 0 0" />
      <geometry>
        <mesh
          filename="package://robot_urdf_infantry/meshes/pitch_link.STL" />
      </geometry>
      <material
        name="">
        <color
          rgba="1 1 1 1" />
      </material>
    </visual>
    <collision>
      <origin
        xyz="0 0 0"
        rpy="0 0 0" />
      <geometry>
        <mesh
          filename="package://robot_urdf_infantry/meshes/pitch_link.STL" />
      </geometry>
    </collision>
  </link>
  <joint
    name="yaw_to_pitch_link"
    type="revolute">
    <origin
      xyz="-0.0192509770102756 -0.0512 0.138131859412924"
      rpy="0 0 0" />
    <parent
      link="yaw_link" />
    <child
      link="pitch_link" />
    <axis
      xyz="0 -1 0" />
    <limit
      lower="-1.05"
      upper="1.5708"
      effort="30"
      velocity="9999" />
    <safety_controller
      soft_upper="1.5708"
      soft_lower="-1.05"
      k_position="9999"
      k_velocity="9999" />
  </joint>
  <link
    name="fire_link">
    <inertial>
      <origin
        xyz="3.0615E-05 3.1297E-05 -0.0069429"
        rpy="0 0 0" />
      <mass
        value="0.067053" />
      <inertia
        ixx="1.8885E-05"
        ixy="-7.341E-08"
        ixz="-4.1722E-08"
        iyy="1.8882E-05"
        iyz="-4.2611E-08"
        izz="3.0274E-05" />
    </inertial>
    <visual>
      <origin
        xyz="0 0 0"
        rpy="0 0 0" />
      <geometry>
        <mesh
          filename="package://robot_urdf_infantry/meshes/fire_link.STL" />
      </geometry>
      <material
        name="">
        <color
          rgba="0.89804 0.91765 0.92941 1" />
      </material>
    </visual>
    <collision>
      <origin
        xyz="0 0 0"
        rpy="0 0 0" />
      <geometry>
        <mesh
          filename="package://robot_urdf_infantry/meshes/fire_link.STL" />
      </geometry>
    </collision>
  </link>
  <joint
    name="base_to_fire_link"
    type="continuous">
    <origin
      xyz="-0.13188 4.8836E-05 0.051212"
      rpy="0 0 0" />
    <parent
      link="base_link" />
    <child
      link="fire_link" />
    <axis
      xyz="0 0 -1" />
    <limit
      effort="360"
      velocity="9999" />
    <safety_controller
      soft_upper="0"
      soft_lower="0"
      k_position="9999"
      k_velocity="9999" />
  </joint>
</robot>